Workbook

Sheet cleaned_data
A1: sme_id | B1: sme_name | C1: province | D1: local_municipality | E1: setting | F1: primary_crop | G1: years_in_operation | H1: num_employees | I1: owner_gender | J1: owner_age_range | K1: business_registration_status | L1: financial_statements_prepared | M1: separate_bank_account | N1: land_ownership_type | O1: title_deed | P1: previous_grant_or_investment | Q1: annual_production_volume_kg | R1: yoy_production_change_pct | S1: production_diversity_count | T1: post_harvest_loss_pct | U1: storage_access | V1: cold_chain_capacity | W1: distance_to_market_km | X1: num_buyers | Y1: formal_offtake_contracts | Z1: avg_price_per_kg_zar | AA1: unit_cost_per_kg_zar | AB1: gross_margin_pct | AC1: outstanding_loan_amount_zar | AD1: loan_repayment_status | AE1: debt_to_revenue_ratio | AF1: certification_status | AG1: export_readiness | AH1: drought_events_5yr | AI1: environmental_shocks_12mo | AJ1: irrigation_present | AK1: electricity_source | AL1: loadshedding_days_per_month | AM1: energy_mitigation_present | AN1: income_seasonality_risk | AO1: pct_women_leadership | AP1: pct_women_workforce | AQ1: pct_youth_employees | AR1: pct_hdi_employees | AS1: sources_from_women_farmers
A2: SME0001 | B2: Thando Boerdery | C2: Western Cape | D2: Hex River Valley | E2: Small town | F2: apples | G2: 19 | H2: 69 | I2: Female | J2: 18-30 | K2: Registered | L2: Yes | M2: Yes | N2: Owned | O2: Unknown | P2: CASP | Q2: 194629 | R2: -6 | S2: 5 | T2: 5.4 | U2: Yes | V2: Yes | W2: 219 | X2: 6 | Y2: Yes | Z2: 16.85 | AA2: 11.76 | AB2: 30.207715 | AC2: 0 | AD2: No Loan | AE2: 0 | AF2: GlobalG.A.P. | AG2: Yes | AH2: 2 | AI2: 1 | AJ2: Yes | AK2: Eskom grid | AL2: 20 | AM2: Yes | AN2: Low | AO2: 35.9 | AP2: 34.1 | AQ2: 16.9 | AR2: 42.6 | AS2: No
A3: SME0002 | B3: Tlhaga Morning | C3: Western Cape | D3: Grabouw | E3: Peri-urban | F3: peaches | G3: 3 | H3: 44 | I3: Female | J3: 51-60 | K3: Registered | L3: Yes | M3: Yes | N3: Owned | O3: Yes | P3: MAFISA | Q3: 317717 | R3: 18.1 | S3: 3 | T3: 7.4 | U3: Yes | V3: Yes | W3: 41 | X3: 12 | Y3: Yes | Z3: 26.83 | AA3: 12.02 | AB3: 55.199404 | AC3: 215958 | AD3: Settled | AE3: 0.025334257 | AF3: Unknown | AG3: No | AH3: 0 | AI3: 1 | AJ3: Yes | AK3: Eskom grid | AL3: 20 | AM3: Yes | AN3: Medium | AO3: 91.3 | AP3: 49.7 | AQ3: 37.3 | AR3: 52.8 | AS3: No
A4: SME0003 | B4: Vhembe Red | C4: Western Cape | D4: Ceres | E4: Small town | F4: pears | G4: 12 | H4: 43 | I4: Male | J4: 60+ | K4: Registered | L4: Yes | M4: Yes | N4: State land | O4: No | P4: Agri-BEE | Q4: 127662 | R4: 25.3 | S4: 1 | T4: 7.3 | U4: Yes | V4: Yes | W4: 37 | X4: 9 | Y4: Yes | Z4: 44.85 | AA4: 25.19 | AB4: 43.835006 | AC4: 0 | AD4: No Loan | AE4: 0 | AF4: Checkers Good Farming | AG4: Yes | AH4: 0 | AI4: 2 | AJ4: Yes | AK4: Solar | AL4: 0 | AM4: Yes | AN4: High | AO4: 0.3 | AP4: 60.5 | AQ4: 37.4 | AR4: 98.3 | AS4: No
A5: SME0004 | B5: Tsebo Red | C5: Western Cape | D5: Ceres | E5: Peri-urban | F5: pears | G5: 20 | H5: 56 | I5: Male | J5: 18-30 | K5: Registered | L5: Yes | M5: Yes | N5: Owned | O5: Yes | P5: CASP | Q5: 270306 | R5: 32.7 | S5: 3 | T5: 8.6 | U5: Yes | V5: Unknown | W5: 45 | X5: 4 | Y5: Yes | Z5: 37.82 | AA5: 28.03 | AB5: 25.885775 | AC5: 100608 | AD5: Settled | AE5: 0.0098413642 | AF5: GlobalG.A.P. | AG5: Yes | AH5: 4 | AI5: 3 | AJ5: Yes | AK5: Eskom grid | AL5: 22 | AM5: No | AN5: Medium | AO5: 71.3 | AP5: 37.9 | AQ5: 35.2 | AR5: 62.4 | AS5: No
A6: SME0005 | B6: Silver Valley | C6: Western Cape | D6: Ceres | E6: Peri-urban | F6: apples | G6: 8 | H6: 23 | I6: Female | J6: 41-50 | K6: Registered | L6: Yes | M6: Yes | N6: Owned | O6: Yes | P6: CASP | Q6: 349565 | R6: -5.7 | S6: 4 | T6: 8.2 | U6: Yes | V6: No | W6: 247 | X6: 6 | Y6: No | Z6: 37.49 | AA6: 15.98 | AB6: 57.3753 | AC6: 344841 | AD6: Current | AE6: 0.026313312 | AF6: Checkers Good Farming | AG6: Yes | AH6: 0 | AI6: 0 | AJ6: Yes | AK6: Solar | AM6: No | AN6: Low | AO6: 24.9 | AP6: 23.3 | AQ6: 25.2 | AR6: 65.3 | AS6: Yes
A7: SME0006 | B7: Tshivhase Silver | C7: Western Cape | D7: Hex River Valley | E7: Small town | F7: apples | G7: 6 | H7: 67 | I7: Male | J7: 51-60 | K7: Informal | L7: Yes | M7: No | N7: Leased | O7: No | P7: LRAD | Q7: 290260 | S7: 2 | T7: 10.7 | U7: No | V7: No | W7: 140 | X7: 10 | Y7: Yes | Z7: 33.17 | AA7: 21.3 | AB7: 35.785348 | AC7: 0 | AD7: No Loan | AE7: 0 | AF7: Woolworths TNC | AG7: Yes | AH7: 1 | AI7: 2 | AJ7: Yes | AK7: Eskom grid | AL7: 8 | AM7: Yes | AN7: High | AO7: 5.7 | AP7: 50.9 | AQ7: 27.6 | AR7: 91.2 | AS7: Yes
A8: SME0007 | B8: Amandla Golden | C8: Western Cape | D8: Hex River Valley | E8: Rural | F8: peaches | G8: 19 | H8: 91 | I8: Female | J8: 60+ | K8: Registered | L8: Yes | M8: Yes | N8: Leased | O8: Unknown | P8: CASP | Q8: 299794 | R8: 19.4 | S8: 5 | T8: 12.8 | U8: No | V8: No | W8: 109 | X8: 8 | Y8: Yes | Z8: 21.44 | AA8: 13.26 | AB8: 38.152985 | AC8: 252942 | AD8: Current | AE8: 0.039352582 | AF8: GlobalG.A.P. | AG8: No | AH8: 4 | AI8: 0 | AJ8: Yes | AK8: Eskom grid | AL8: 16 | AM8: Yes | AN8: High | AO8: 88.1 | AP8: 71.5 | AQ8: 21.6 | AR8: 49.5 | AS8: No
A9: SME0008 | B9: Ubuntu Plaas | C9: Western Cape | D9: Hex River Valley | E9: Peri-urban | F9: tomatoes | G9: 23 | H9: 58 | I9: Male | J9: 41-50 | K9: Registered | L9: Yes | M9: Yes | N9: Leased | O9: Yes | P9: DTIC | Q9: 336131 | R9: -4.9 | S9: 1 | T9: 6.4 | U9: Yes | V9: Yes | W9: 6 | X9: 8 | Y9: No | Z9: 30.85 | AA9: 14.03 | AB9: 54.52188 | AC9: 0 | AD9: No Loan | AE9: 0 | AF9: Fairtrade | AG9: Yes | AH9: 0 | AI9: 0 | AJ9: Yes | AK9: Eskom grid | AL9: 22 | AM9: Yes | AN9: Low | AO9: 83.5 | AP9: 50.8 | AQ9: 11.7 | AR9: 47.6 | AS9: Yes
A10: SME0009 | B10: Mashamba Rainbow | C10: Western Cape | D10: Ceres | E10: Peri-urban | F10: apples | G10: 8 | H10: 10 | I10: Male | J10: 51-60 | K10: Registered | L10: No | M10: Yes | N10: Leased | O10: Yes | P10: CASP | Q10: 174036 | R10: 24.2 | S10: 3 | T10: 16.7 | U10: Yes | V10: Yes | W10: 132 | X10: 7 | Y10: Yes | Z10: 33.35 | AA10: 16.78 | AB10: 49.685157 | AC10: 376552 | AD10: Current | AE10: 0.064876891 | AF10: SIZA | AG10: No | AH10: 1 | AI10: 1 | AJ10: Yes | AK10: Eskom grid | AL10: 18 | AM10: Yes | AN10: Low | AO10: 96.7 | AP10: 29.5 | AQ10: 33.9 | AR10: 64 | AS10: No
A11: SME0010 | B11: Green Valley | C11: Western Cape | D11: Hex River Valley | E11: Rural | F11: table grapes | G11: 24 | H11: 115 | I11: Male | J11: 51-60 | K11: Registered | L11: No | M11: Yes | N11: Owned | O11: Yes | P11: DTIC | Q11: 5000 | R11: -13.1 | S11: 5 | T11: 7.9 | U11: Yes | V11: Yes | W11: 271 | X11: 11 | Y11: Yes | Z11: 42.67 | AA11: 27.51 | AB11: 35.528474 | AC11: 345038 | AD11: Current | AE11: 1.6172393 | AF11: Woolworths TNC | AG11: No | AH11: 0 | AI11: 2 | AJ11: Yes | AK11: Generator | AL11: 6 | AM11: Yes | AN11: High | AO11: 55.4 | AP11: 23.4 | AQ11: 34.9 | AR11: 62.7 | AS11: No
A12: SME0011 | B12: Siyabonga Plaas | C12: Western Cape | D12: Hex River Valley | E12: Peri-urban | F12: table grapes | G12: 15 | H12: 101 | I12: Male | J12: 60+ | K12: Registered | L12: Yes | M12: Yes | N12: Owned | O12: Unknown | P12: Agri-BEE | Q12: 496145 | R12: 34.1 | S12: 2 | T12: 14.9 | U12: Yes | V12: Yes | W12: 176 | X12: 4 | Y12: No | Z12: 35.29 | AA12: 21.85 | AB12: 38.084443 | AC12: 159304 | AD12: In Arrears | AE12: 0.0090984289 | AF12: Organic (CERES) | AG12: No | AH12: 0 | AI12: 3 | AJ12: Yes | AK12: Solar | AL12: 0 | AM12: Yes | AN12: High | AO12: 49.4 | AP12: 27.1 | AQ12: 34.5 | AR12: 40.3 | AS12: No
A13: SME0012 | B13: Silver Valley | C13: Western Cape | D13: Ceres | E13: Peri-urban | F13: avocados | G13: 22 | H13: 82 | I13: Male | J13: 51-60 | K13: Registered | L13: Yes | M13: Yes | N13: Owned | O13: Yes | P13: DTIC | Q13: 457106 | R13: 33.5 | S13: 4 | T13: 17.5 | U13: Yes | V13: No | W13: 248 | X13: 10 | Y13: Yes | Z13: 15.64 | AA13: 9.46 | AB13: 39.514066 | AC13: 0 | AD13: No Loan | AE13: 0 | AF13: Fairtrade | AG13: No | AH13: 2 | AI13: 3 | AJ13: Yes | AK13: Eskom grid | AL13: 19 | AM13: Yes | AN13: High | AO13: 89.3 | AP13: 15.6 | AQ13: 11.8 | AR13: 63 | AS13: Yes
A14: SME0013 | B14: Lentswe Sunrise | C14: Western Cape | D14: Villiersdorp | E14: Small town | F14: table grapes | G14: 28 | H14: 112 | I14: Male | J14: 51-60 | K14: Registered | L14: No | M14: Yes | N14: Owned | O14: Yes | P14: CASP | Q14: 264422 | R14: -2.1 | S14: 4 | T14: 17.8 | U14: No | V14: No | W14: 219 | X14: 11 | Y14: Yes | Z14: 27.3 | AA14: 16.14 | AB14: 40.879121 | AC14: 175537 | AD14: Current | AE14: 0.024316913 | AF14: GlobalG.A.P. | AG14: No | AH14: 3 | AI14: 1 | AJ14: Yes | AK14: Solar | AL14: 0 | AM14: No | AN14: Low | AO14: 90.7 | AP14: 51.4 | AQ14: 34.8 | AR14: 45 | AS14: No
A15: SME0014 | B15: Mupo Thando | C15: Western Cape | D15: Grabouw | E15: Peri-urban | F15: plums | G15: 9 | H15: 25 | I15: Male | J15: 18-30 | K15: Registered | L15: Yes | M15: Yes | N15: Owned | O15: Yes | P15: None | Q15: 362810 | R15: -16.9 | S15: 3 | T15: 8.4 | U15: Yes | V15: No | W15: 25 | X15: 3 | Y15: No | Z15: 13.78 | AA15: 4.94 | AB15: 64.150943 | AC15: 100977 | AD15: Settled | AE15: 0.020197332 | AF15: Organic (CERES) | AG15: Yes | AH15: 2 | AI15: 2 | AJ15: Yes | AK15: Eskom grid | AL15: 17 | AM15: No | AN15: Low | AO15: 77.8 | AP15: 21.5 | AQ15: 19 | AR15: 74.7 | AS15: No
A16: SME0015 | B16: Tlhaga Thando | C16: Western Cape | D16: Ceres | E16: Small town | F16: apples | G16: 26 | H16: 87 | I16: Female | J16: N/A | K16: Registered | L16: Yes | M16: Yes | N16: Owned | O16: No | P16: DTIC | Q16: 304593 | R16: 19.7 | S16: 1 | T16: 12.6 | U16: Yes | V16: Unknown | W16: 255 | X16: 4 | Y16: Yes | Z16: 20.13 | AA16: 14.22 | AB16: 29.359165 | AC16: 122393 | AD16: Settled | AE16: 0.019961487 | AF16: Organic (CERES) | AG16: Yes | AH16: 4 | AI16: 3 | AJ16: Yes | AK16: Solar | AL16: 0 | AM16: No | AN16: High | AO16: 32.2 | AP16: 27.2 | AQ16: 47.1 | AR16: 56.7 | AS16: No
A17: SME0016 | B17: Sunrise Plaas | C17: Western Cape | D17: Hex River Valley | E17: Peri-urban | F17: plums | G17: 18 | H17: 16 | I17: Male | J17: 18-30 | K17: Registered | L17: Yes | M17: Yes | N17: Owned | O17: Yes | P17: LRAD | Q17: 457526 | R17: 4.4 | S17: 5 | T17: 16.4 | U17: Yes | V17: Yes | W17: 256 | X17: 10 | Y17: No | Z17: 9.63 | AA17: 4.22 | AB17: 56.178609 | AC17: 0 | AD17: No Loan | AE17: 0 | AF17: SIZA | AG17: No | AH17: 3 | AI17: 2 | AJ17: No | AK17: Solar | AL17: 0 | AM17: Yes | AN17: High | AO17: 70.3 | AP17: 29 | AQ17: 16.3 | AR17: 47.2 | AS17: Yes
A18: SME0017 | B18: Tshivhase Siyabonga | C18: Western Cape | D18: Ceres | E18: Peri-urban | F18: plums | G18: 27 | H18: 39 | I18: Male | J18: 31-40 | K18: Registered | L18: No | M18: Yes | N18: Owned | O18: Yes | P18: MAFISA | Q18: 174079 | R18: -1.9 | S18: 5 | T18: 6.9 | U18: Yes | V18: Yes | W18: 154 | X18: 5 | Y18: Yes | Z18: 35.36 | AA18: 13.83 | AB18: 60.888009 | AC18: 227471 | AD18: Current | AE18: 0.036954506 | AF18: Unknown | AG18: Yes | AH18: 3 | AI18: 0 | AJ18: Yes | AK18: Eskom grid | AL18: 14 | AM18: Yes | AN18: Low | AO18: 15.2 | AP18: 66.8 | AQ18: 47.7 | AR18: 45.1 | AS18: Yes
A19: SME0018 | B19: Mupo Green | C19: Western Cape | D19: Villiersdorp | E19: Peri-urban | F19: plums | G19: 20 | H19: 109 | I19: Female | J19: 31-40 | K19: Registered | L19: No | M19: Yes | N19: Owned | O19: Yes | P19: None | Q19: 190637 | R19: -4.1 | S19: 1 | T19: 7.4 | U19: Yes | V19: Yes | W19: 6 | X19: 9 | Y19: Yes | Z19: 29.16 | AA19: 13.6 | AB19: 53.360768 | AC19: 565565 | AD19: Current | AE19: 0.10173908 | AF19: GlobalG.A.P. | AG19: Yes | AH19: 2 | AI19: 1 | AJ19: Yes | AK19: Solar | AL19: 0 | AM19: Yes | AN19: Medium | AO19: 90.8 | AP19: 67.9 | AQ19: 8.2 | AR19: 50 | AS19: Yes
... A22: SME0021 | B22: Tlhaga Blue | C22: Western Cape | D22: Grabouw | E22: Small town | F22: peaches | G22: 13 | H22: 39 | I22: Male | J22: 18-30 | K22: Registered | L22: Yes | M22: No | N22: Leased | O22: Yes | P22: MAFISA | Q22: 485104 | R22: 27.4 | S22: 4 | T22: 10.1 | U22: Yes | V22: Yes | W22: 6 | X22: 7 | Y22: Yes | Z22: 38.66 | AA22: 22.5 | AB22: 41.80031 | AC22: 0 | AD22: No Loan | AE22: 0 | AF22: Checkers Good Farming | AG22: Yes | AH22: 3 | AI22: 2 | AJ22: Yes | AK22: Solar | AL22: 0 | AM22: Yes | AN22: High | AO22: 93.3 | AP22: 70.9 | AQ22: 49.1 | AR22: 54.3 | AS22: No
A23: SME0022 | B23: Silver Valley | C23: Western Cape | D23: Villiersdorp | E23: Peri-urban | F23: plums | G23: 5 | H23: 79 | I23: Male | J23: 18-30 | K23: Informal | L23: Yes | M23: Yes | N23: Owned | O23: Yes | P23: Agri-BEE | Q23: 132277 | S23: 4 | T23: 5.2 | U23: Yes | V23: No | W23: 84 | X23: 4 | Y23: Yes | Z23: 43.8 | AA23: 21.26 | AB23: 51.461187 | AC23: 0 | AD23: No Loan | AE23: 0 | AF23: Woolworths TNC | AG23: No | AH23: 4 | AI23: 3 | AJ23: Yes | AK23: Solar | AL23: 0 | AM23: No | AN23: High | AO23: 87.2 | AP23: 12.5 | AQ23: 8.1 | AR23: 77.9 | AS23: No
A24: SME0023 | B24: Lentswe Themba | C24: Western Cape | D24: Hex River Valley | E24: Peri-urban | F24: apples | G24: 10 | H24: 60 | I24: Male | J24: 51-60 | K24: Registered | L24: Yes | M24: Yes | N24: Owned | O24: Yes | P24: LRAD | Q24: 208029 | S24: 5 | T24: 15.2 | U24: Yes | V24: Yes | W24: 200 | X24: 12 | Y24: Yes | Z24: 25.41 | AA24: 14.82 | AB24: 41.676505 | AC24: 510324 | AD24: Settled | AE24: 0.096542257 | AF24: Unknown | AG24: No | AH24: 2 | AI24: 1 | AJ24: No | AK24: Eskom grid | AL24: 15 | AM24: Unknown | AN24: High | AO24: 63.9 | AP24: 39.7 | AQ24: 16.3 | AR24: 90.7 | AS24: Yes
A25: SME0024 | B25: Vhembe Ubuntu | C25: Western Cape | D25: Ceres | E25: Small town | F25: plums | G25: 9 | H25: 16 | I25: Female | J25: 60+ | K25: Registered | L25: No | M25: Yes | N25: Owned | O25: Yes | P25: None | Q25: 340428 | R25: 30 | S25: 3 | T25: 16.6 | U25: Yes | V25: No | W25: 117 | X25: 6 | Y25: Yes | Z25: 32.43 | AA25: 20.7 | AB25: 36.170213 | AC25: 0 | AD25: No Loan | AE25: 0 | AF25: GlobalG.A.P. | AG25: No | AH25: 0 | AI25: 2 | AJ25: Yes | AK25: Solar | AL25: 0 | AM25: Yes | AN25: Medium | AO25: 9 | AP25: 30.7 | AQ25: 38.6 | AR25: 50.5 | AS25: Yes
A26: SME0025 | B26: Izifundo Themba | C26: Western Cape | D26: Ceres | E26: Peri-urban | F26: table grapes | G26: 3 | H26: 33 | I26: Male | J26: 51-60 | K26: Registered | L26: Yes | M26: No | N26: State land | O26: No | P26: DTIC | Q26: 271771 | R26: -14.6 | S26: 4 | T26: 5.2 | U26: Yes | V26: Yes | W26: 139 | X26: 12 | Y26: Yes | Z26: 30.9 | AA26: 15.41 | AB26: 50.12945 | AC26: 0 | AD26: No Loan | AE26: 0 | AF26: Fairtrade | AG26: No | AH26: 4 | AI26: 2 | AJ26: Yes | AK26: Generator | AL26: 5 | AM26: Yes | AN26: High | AP26: 31.2 | AQ26: 23.4 | AR26: 48.4 | AS26: No
A27: SME0026 | B27: Tshivhase Heritage | C27: Limpopo | D27: Tzaneen | E27: Small town | F27: litchis | G27: 19 | H27: 110 | I27: Male | J27: 51-60 | K27: Registered | L27: Yes | M27: Yes | N27: Owned | O27: Yes | P27: None | Q27: 131915 | R27: 30 | S27: 5 | T27: 11.1 | U27: No | V27: No | W27: 21 | X27: 8 | Y27: Yes | Z27: 23.34 | AA27: 10.37 | AB27: 55.569837 | AC27: 784742 | AD27: Settled | AE27: 0.25487771 | AF27: SIZA | AG27: Yes | AH27: 1 | AI27: 0 | AJ27: Yes | AK27: Generator | AL27: 3 | AM27: Yes | AN27: Low | AO27: 5.1 | AP27: 33.3 | AQ27: 49.5 | AR27: 87.2 | AS27: Yes
A28: SME0027 | B28: Themba Laan | C28: Limpopo | D28: Letsitele | E28: Rural | F28: avocados | G28: 18 | H28: 47 | I28: Male | J28: 18-30 | K28: Registered | L28: Yes | M28: Yes | N28: Leased | O28: No | P28: None | Q28: 93516 | R28: -12.1 | S28: 3 | T28: 16.8 | U28: Yes | V28: Yes | W28: 94 | X28: 7 | Y28: Yes | Z28: 34.93 | AA28: 19.58 | AB28: 43.945033 | AC28: 0 | AD28: No Loan | AE28: 0 | AF28: Fairtrade | AG28: No | AH28: 4 | AI28: 0 | AJ28: Yes | AK28: Generator | AL28: 10 | AM28: Yes | AN28: High | AO28: 45.8 | AP28: 77.5 | AQ28: 7.7 | AR28: 68.7 | AS28: No
A29: SME0028 | B29: Mashamba Rainbow | C29: Limpopo | D29: Bela-Bela | E29: Rural | F29: mangoes | G29: 13 | H29: 91 | I29: Male | J29: 51-60 | K29: Registered | L29: Yes | M29: Yes | N29: Owned | O29: Yes | P29: DTIC | Q29: 397418 | R29: 5.8 | S29: 1 | T29: 17.8 | U29: Yes | V29: Yes | W29: 115 | X29: 9 | Y29: Yes | Z29: 14.91 | AA29: 7.24 | AB29: 51.441985 | AC29: 332792 | AD29: Current | AE29: 0.056162664 | AF29: SIZA | AG29: Yes | AH29: 1 | AI29: 3 | AJ29: Yes | AK29: Eskom grid | AL29: 9 | AM29: Yes | AN29: Low | AO29: 74.5 | AP29: 36.1 | AQ29: 10.9 | AR29: 43.6 | AS29: No
A30: SME0029 | B30: Morning Ridge | C30: Limpopo | D30: Bela-Bela | E30: Small town | F30: avocados | G30: 20 | H30: 54 | I30: Male | J30: 18-30 | K30: Informal | L30: Yes | M30: No | N30: Owned | O30: Yes | P30: DTIC | Q30: 346030 | R30: -7.2 | S30: 4 | T30: 8.4 | U30: Yes | V30: No | W30: 193 | X30: 4 | Y30: No | Z30: 28.39 | AA30: 19.1 | AB30: 32.72279 | AC30: 0 | AD30: No Loan | AE30: 0 | AF30: Organic (CERES) | AG30: No | AH30: 4 | AI30: 0 | AJ30: No | AK30: Solar | AL30: 0 | AM30: No | AN30: High | AO30: 2.9 | AP30: 29.1 | AQ30: 39.3 | AR30: 95.3 | AS30: No
A31: SME0030 | B31: Amandla Green | C31: Limpopo | D31: Bela-Bela | E31: Rural | F31: mangoes | G31: 14 | H31: 73 | I31: Male | J31: 31-40 | K31: Registered | L31: No | M31: Yes | N31: Owned | O31: Yes | P31: MAFISA | Q31: 23198 | R31: 23.3 | S31: 5 | T31: 13.9 | U31: Yes | V31: Yes | W31: 30 | X31: 4 | Y31: Yes | Z31: 31.82 | AA31: 17.32 | AB31: 45.568825 | AC31: 218533 | AD31: Current | AE31: 0.29605085 | AF31: SIZA | AG31: Yes | AH31: 4 | AI31: 3 | AJ31: Yes | AK31: Solar | AL31: 0 | AM31: Yes | AN31: High | AO31: 98.4 | AP31: 13.8 | AQ31: 14.2 | AR31: 96.7 | AS31: No
A32: SME0031 | B32: Tshivhase Red | C32: Limpopo | D32: Tzaneen | E32: Peri-urban | F32: mangoes | G32: 3 | H32: 65 | I32: Female | J32: 51-60 | K32: Registered | L32: Yes | M32: Yes | N32: Owned | O32: Yes | P32: CASP | Q32: 18587 | R32: 35.3 | S32: 3 | T32: 13.6 | U32: Yes | V32: Yes | W32: 218 | Y32: Yes | Z32: 6.81 | AA32: 3.27 | AB32: 51.982379 | AC32: 0 | AD32: No Loan | AE32: 0 | AF32: Woolworths TNC | AG32: No | AH32: 2 | AI32: 0 | AJ32: Yes | AK32: Generator | AL32: 3 | AM32: Yes | AN32: Low | AO32: 39.6 | AP32: 31.7 | AQ32: 20.3 | AR32: 60 | AS32: Yes
A33: SME0032 | B33: Andile Hoek | C33: Limpopo | D33: Levubu | E33: Small town | F33: avocados | G33: 7 | H33: 37 | I33: Male | J33: 18-30 | K33: Informal | L33: Yes | M33: Yes | N33: Owned | O33: Yes | P33: LRAD | Q33: 485194 | R33: 17.7 | S33: 4 | T33: 16.3 | U33: Yes | V33: Yes | W33: 170 | X33: 8 | Y33: Yes | Z33: 8.66 | AA33: 4.56 | AB33: 47.344111 | AC33: 219739 | AD33: In Arrears | AE33: 0.052296645 | AF33: SIZA | AG33: Yes | AH33: 0 | AI33: 2 | AJ33: Yes | AK33: Eskom grid | AL33: 9 | AM33: No | AN33: Low | AO33: 61.5 | AP33: 45.5 | AQ33: 25.8 | AR33: 73.3 | AS33: No
A34: SME0033 | B34: Lentswe Morning | C34: Limpopo | D34: Letsitele | E34: Small town | F34: spinach | G34: 23 | H34: 25 | I34: Male | J34: 18-30 | K34: Registered | L34: Yes | M34: Yes | N34: Owned | O34: Yes | P34: LRAD | Q34: 450997 | R34: 6.3 | S34: 4 | T34: 12.9 | U34: Yes | V34: Yes | W34: 149 | X34: 9 | Y34: Yes | Z34: 19.2 | AA34: 11.31 | AB34: 41.09375 | AC34: 0 | AD34: No Loan | AE34: 0 | AF34: Woolworths TNC | AG34: Yes | AH34: 0 | AI34: 3 | AJ34: Yes | AK34: Eskom grid | AL34: 12 | AM34: Yes | AN34: Medium | AO34: 33.3 | AP34: 50.8 | AQ34: 11.4 | AR34: 61 | AS34: No
A35: SME0034 | B35: Kopano Blue | C35: Limpopo | D35: Levubu | E35: Peri-urban | F35: tomatoes | G35: 21 | H35: 100 | I35: Male | J35: 60+ | K35: Registered | L35: Yes | M35: Yes | N35: Owned | O35: Yes | P35: MAFISA | Q35: 89558 | R35: 1.8 | S35: 2 | T35: 19.3 | U35: Yes | V35: Yes | W35: 103 | X35: 6 | Y35: No | Z35: 12.04 | AA35: 5.64 | AB35: 53.156146 | AC35: 0 | AD35: No Loan | AE35: 0 | AF35: Fairtrade | AG35: Yes | AH35: 4 | AI35: 0 | AJ35: Yes | AK35: Eskom grid | AL35: 22 | AM35: Yes | AN35: High | AO35: 15.4 | AP35: 22.7 | AQ35: 36.2 | AR35: 77.5 | AS35: No
A36: SME0035 | B36: Siyabonga Boerdery | C36: Limpopo | D36: Levubu | E36: Peri-urban | F36: litchis | G36: 10 | H36: 118 | I36: Male | J36: 31-40 | K36: Registered | L36: Yes | M36: Yes | N36: Leased | O36: Yes | P36: MAFISA | Q36: 435630 | R36: 36.8 | S36: 4 | T36: 11.9 | U36: Yes | V36: Yes | W36: 275 | X36: 9 | Y36: No | Z36: 37.86 | AA36: 25.39 | AB36: 32.937137 | AC36: 200003 | AD36: Current | AE36: 0.012126574 | AF36: Fairtrade | AG36: Yes | AH36: 4 | AI36: 0 | AJ36: Yes | AK36: Eskom grid | AL36: 9 | AM36: Yes | AN36: Medium | AO36: 83.1 | AP36: 16.4 | AQ36: 46 | AR36: 89 | AS36: No
A37: SME0036 | B37: Tsebo Golden | C37: Limpopo | D37: Bela-Bela | E37: Peri-urban | F37: tomatoes | G37: 27 | H37: 106 | I37: Male | J37: 31-40 | K37: Registered | L37: No | M37: Yes | N37: Owned | O37: Yes | P37: LRAD | Q37: 79840 | R37: -2.8 | S37: 4 | T37: 15.4 | U37: Yes | V37: Yes | W37: 234 | X37: 12 | Y37: Yes | Z37: 9.09 | AA37: 4.11 | AB37: 54.785479 | AC37: 0 | AD37: No Loan | AE37: 0 | AF37: Unknown | AG37: No | AH37: 4 | AI37: 3 | AJ37: Yes | AK37: Eskom grid | AL37: 20 | AM37: Unknown | AN37: Low | AO37: 23.8 | AP37: 54.7 | AQ37: 33 | AR37: 43.8 | AS37: No
A38: SME0037 | B38: Tlhaga Blue | C38: Limpopo | D38: Letsitele | E38: Peri-urban | F38: avocados | G38: 17 | H38: 61 | I38: Female | J38: 60+ | K38: Registered | L38: Yes | M38: Yes | N38: Owned | O38: Yes | P38: DTIC | Q38: 345985 | R38: 27.2 | S38: 5 | T38: 13.3 | U38: Yes | V38: Yes | W38: 203 | X38: 8 | Y38: Yes | Z38: 6.63 | AA38: 4.41 | AB38: 33.484163 | AC38: 586353 | AD38: Settled | AE38: 0.25561619 | AF38: Woolworths TNC | AG38: Yes | AH38: 0 | AI38: 2 | AJ38: Yes | AK38: Solar | AL38: 0 | AM38: Unknown | AN38: High | AO38: 98.1 | AP38: 43.5 | AQ38: 13.2 | AR38: 48.1 | AS38: No
A39: SME0038 | B39: Kopano Ubuntu | C39: Limpopo | D39: Letsitele | E39: Rural | F39: mangoes | G39: 9 | H39: 19 | I39: Male | J39: 41-50 | K39: Registered | L39: Yes | M39: Yes | N39: Owned | O39: Yes | P39: MAFISA | Q39: 489385 | R39: -17.1 | S39: 3 | T39: 9.1 | U39: Yes | V39: Unknown | W39: 209 | X39: 10 | Y39: No | Z39: 21.08 | AA39: 15.59 | AB39: 26.043643 | AC39: 398019 | AD39: Settled | AE39: 0.038581805 | AF39: SIZA | AG39: Yes | AH39: 3 | AI39: 0 | AJ39: Yes | AK39: Generator | AL39: 4 | AM39: Yes | AN39: Low | AO39: 32.8 | AP39: 30.7 | AQ39: 25.1 | AR39: 83.1 | AS39: Yes
A40: SME0039 | B40: Tlhaga Red | C40: Limpopo | D40: Tzaneen | E40: Small town | F40: avocados | G40: 22 | H40: 96 | I40: Male | J40: 41-50 | K40: Informal | L40: Yes | M40: No | N40: Owned | O40: No | P40: DTIC | Q40: 473162 | R40: 20.8 | S40: 1 | T40: 7.1 | U40: Yes | V40: Yes | W40: 22 | X40: 5 | Y40: Yes | Z40: 36.36 | AA40: 18.05 | AB40: 50.357536 | AC40: 453796 | AD40: Settled | AE40: 0.026377093 | AF40: Fairtrade | AG40: Yes | AH40: 3 | AI40: 0 | AJ40: Yes | AK40: Solar | AL40: 0 | AM40: Yes | AN40: High | AO40: 65 | AP40: 27.5 | AQ40: 10.1 | AR40: 84.1 | AS40: No
A41: SME0040 | B41: Mupo Siyabonga | C41: Limpopo | D41: Levubu | E41: Rural | F41: citrus | G41: 5 | H41: 24 | I41: Male | J41: 31-40 | K41: Informal | L41: Yes | M41: No | N41: Owned | O41: No | P41: None | Q41: 313366 | R41: 39.8 | S41: 3 | T41: 15 | U41: Yes | V41: Yes | W41: 153 | X41: 7 | Y41: No | Z41: 33.76 | AA41: 24.34 | AB41: 27.902844 | AC41: 634957 | AD41: Current | AE41: 0.060019172 | AF41: Organic (CERES) | AG41: No | AH41: 1 | AI41: 3 | AJ41: Yes | AK41: Eskom grid | AL41: 13 | AM41: Yes | AN41: Medium | AO41: 61.2 | AP41: 16 | AQ41: 18.9 | AR41: 100 | AS41: No
A42: SME0041 | B42: Tshivhase Old | C42: Limpopo | D42: Tzaneen | E42: Peri-urban | F42: litchis | G42: 25 | H42: 31 | I42: Male | J42: 60+ | K42: Registered | L42: Yes | M42: Yes | N42: Leased | O42: Yes | P42: CASP | Q42: 145096 | R42: 11.1 | S42: 3 | T42: 7.5 | U42: Yes | V42: Yes | W42: 182 | X42: 11 | Y42: No | Z42: 38.99 | AA42: 17.55 | AB42: 54.988459 | AC42: 440673 | AD42: Current | AE42: 0.077894675 | AF42: Woolworths TNC | AG42: Yes | AH42: 1 | AI42: 1 | AJ42: Yes | AK42: Eskom grid | AL42: 18 | AM42: No | AN42: High | AO42: 84.3 | AP42: 49.5 | AQ42: 42.1 | AR42: 41.7 | AS42: Yes
...

Sheet Score_Calculations
A1: sme_id | B1: sme_name | C1: business_registration_status | D1: financial_statements_prepared | E1: separate_bank_account | F1: title_deed | G1: land_ownership_type | H1: years_in_operation | I1: previous_grant_or_investment | J1: num_employees | K1: annual_production_volume_kg | L1: post_harvest_loss_pct | M1: storage_access | N1: cold_chain_capacity | O1: production_diversity_count | P1: gross_margin_pct | Q1: num_buyers | R1: formal_offtake_contracts | S1: certification_status | T1: export_readiness | U1: loan_repayment_status | V1: debt_to_revenue_ratio | W1: irrigation_present | X1: energy_mitigation_present | Y1: electricity_source | Z1: loadshedding_days_per_month | AA1: drought_events_5yr | AB1: pct_women_leadership | AC1: pct_women_workforce | AD1: pct_youth_employees | AE1: pct_hdi_employees | AF1: sources_from_women_farmers
A2: SME0001 | B2: Thando Boerdery | C2: =IF(cleaned_data!K2="Registered",1,0) -> 1 | D2: =IF(cleaned_data!L2="Yes",1,0) -> 1 | E2: =IF(cleaned_data!M2="Yes",1,0) -> 1 | F2: =IF(cleaned_data!O2="Unknown","",IF(cleaned_data!O2="Yes",1,0)) | G2: {=_xlfn.IFS(cleaned_data!N2="Owned",1,cleaned_data!N2="Leased",0.75,cleaned_data!N2="State land",0.5,cleaned_data!N2="Communal",0.25)} -> 1 | H2: {=_xlfn.IFS(cleaned_data!G2>=10,1,cleaned_data!G2>=5,0.75,cleaned_data!G2>=2,0.5,TRUE,0.25)} -> 1 | I2: =IF(cleaned_data!P2="None",0,1) -> 1 | J2: {=_xlfn.IFS(cleaned_data!H2>=20,1,cleaned_data!H2>=10,0.75,cleaned_data!H2>=5,0.5,cleaned_data!H2>=1,0.25,TRUE,0)} -> 1 | K2: {=_xlfn.IFS(cleaned_data!Q2>=100000,1,cleaned_data!Q2>=50000,0.75,cleaned_data!Q2>=10000,0.5,TRUE,0.25)} -> 1 | L2: {=_xlfn.IFS(cleaned_data!T2="","",cleaned_data!T2<=10,1,cleaned_data!T2<=25,0.75,cleaned_data!T2<=40,0.5, cleaned_data!T2>40,0.25)} -> 1 | M2: =IF(cleaned_data!U2="Yes",1,0) -> 1 | N2: {=_xlfn.IFS(cleaned_data!V2="Unknown","",cleaned_data!V2="Yes",1,TRUE,0)} -> 1 | O2: {=_xlfn.IFS(cleaned_data!S2>=4,1,cleaned_data!S2=3,0.75,cleaned_data!S2=2,0.5,cleaned_data!S2=1,0.25,TRUE,0)} -> 1 | P2: {=_xlfn.IFS(cleaned_data!AB2>=50,1,cleaned_data!AB2>=35,0.75,cleaned_data!AB2>=20,0.5,TRUE,0.25)} -> 0.5 | Q2: {=_xlfn.IFS(cleaned_data!X2>=5,1,cleaned_data!X2>=3,0.75,cleaned_data!X2=2,0.5,cleaned_data!X2=1,0.25,TRUE,0)} -> 1 | R2: =IF(cleaned_data!Y2="Yes",1,0) -> 1 | S2: =IF(OR(cleaned_data!AF2="GlobalG.A.P.",cleaned_data!AF2="Fairtrade",cleaned_data!AF2="Organic (CERES)"),1, IF(OR(cleaned_data!AF2="SIZA",cleaned_data!AF2="Woolworths TNC",cleaned_data!AF2="Checkers Good Farming"),0.75, IF(cleaned_data!AF2="No Certificate",0, IF(cleaned_data!AF2="Unknown","","")))) -> 1 | T2: =IF(cleaned_data!AG2="Yes",1,0) -> 1 | U2: =IF(OR(cleaned_data!AD2="No Loan",cleaned_data!AD2="Settled",cleaned_data!AD2="Current"),1, IF(cleaned_data!AD2="In Arrears",0.5, IF(cleaned_data!AD2="Defaulted",0, IF(cleaned_data!AD2="Unknown","","")))) -> 1 | V2: {=_xlfn.IFS(cleaned_data!AE2<=0.2,1, cleaned_data!AE2<=0.5,0.75, cleaned_data!AE2<=1,0.5, cleaned_data!AE2>1,0.25)} -> 1 | W2: =IF(cleaned_data!AJ2="Yes",1,0) -> 1 | X2: {=_xlfn.IFS(cleaned_data!AM2="Yes", 1, cleaned_data!AM2="No", 0, cleaned_data!AM2="Unknown", "")} -> 1 | Y2: {=_xlfn.IFS(cleaned_data!AK2="Solar", 1, cleaned_data!AK2="Generator", 0.75, cleaned_data!AK2="Eskom grid", 0.5, TRUE, "")} -> 0.5 | Z2: {=_xlfn.IFS(cleaned_data!AL2="", "", cleaned_data!AL2<=8, 1, cleaned_data!AL2<=14, 0.75, cleaned_data!AL2<=21, 0.5, cleaned_data!AL2>=22, 0.25)} -> 0.5 | AA2: {=_xlfn.IFS(cleaned_data!AH2=0, 1, cleaned_data!AH2=1, 0.75, cleaned_data!AH2=2, 0.5, cleaned_data!AH2>=3, 0.25)} -> 0.5 | AB2: {=_xlfn.IFS(cleaned_data!AO2="", "", cleaned_data!AO2>=50, 1, cleaned_data!AO2>=30, 0.75, cleaned_data!AO2>=10, 0.5, cleaned_data!AO2<10, 0.25)} -> 0.75 | AC2: {=_xlfn.IFS(cleaned_data!AP2>=50,1, cleaned_data!AP2>=30,0.75, cleaned_data!AP2>=10,0.5, cleaned_data!AP2<10,0.25)} -> 0.75 | AD2: {=_xlfn.IFS(cleaned_data!AQ2>=30,1, cleaned_data!AQ2>=20,0.75, cleaned_data!AQ2>=10,0.5, cleaned_data!AQ2<10,0.25)} -> 0.5 | AE2: {=_xlfn.IFS(cleaned_data!AR2>=75,1, cleaned_data!AR2>=50,0.75, cleaned_data!AR2>=25,0.5, cleaned_data!AR2<25,0.25)} -> 0.5 | AF2: =IF(cleaned_data!AS2="Yes",1,0) -> 0
A3: SME0002 | B3: Tlhaga Morning | C3: =IF(cleaned_data!K3="Registered",1,0) -> 1 | D3: =IF(cleaned_data!L3="Yes",1,0) -> 1 | E3: =IF(cleaned_data!M3="Yes",1,0) -> 1 | F3: =IF(cleaned_data!O3="Unknown","",IF(cleaned_data!O3="Yes",1,0)) -> 1 | G3: {=_xlfn.IFS(cleaned_data!N3="Owned",1,cleaned_data!N3="Leased",0.75,cleaned_data!N3="State land",0.5,cleaned_data!N3="Communal",0.25)} -> 1 | H3: {=_xlfn.IFS(cleaned_data!G3>=10,1,cleaned_data!G3>=5,0.75,cleaned_data!G3>=2,0.5,TRUE,0.25)} -> 0.5 | I3: =IF(cleaned_data!P3="None",0,1) -> 1 | J3: {=_xlfn.IFS(cleaned_data!H3>=20,1,cleaned_data!H3>=10,0.75,cleaned_data!H3>=5,0.5,cleaned_data!H3>=1,0.25,TRUE,0)} -> 1 | K3: {=_xlfn.IFS(cleaned_data!Q3>=100000,1,cleaned_data!Q3>=50000,0.75,cleaned_data!Q3>=10000,0.5,TRUE,0.25)} -> 1 | L3: {=_xlfn.IFS(cleaned_data!T3="","",cleaned_data!T3<=10,1,cleaned_data!T3<=25,0.75,cleaned_data!T3<=40,0.5, cleaned_data!T3>40,0.25)} -> 1 | M3: =IF(cleaned_data!U3="Yes",1,0) -> 1 | N3: {=_xlfn.IFS(cleaned_data!V3="Unknown","",cleaned_data!V3="Yes",1,TRUE,0)} -> 1 | O3: {=_xlfn.IFS(cleaned_data!S3>=4,1,cleaned_data!S3=3,0.75,cleaned_data!S3=2,0.5,cleaned_data!S3=1,0.25,TRUE,0)} -> 0.75 | P3: {=_xlfn.IFS(cleaned_data!AB3>=50,1,cleaned_data!AB3>=35,0.75,cleaned_data!AB3>=20,0.5,TRUE,0.25)} -> 1 | Q3: {=_xlfn.IFS(cleaned_data!X3>=5,1,cleaned_data!X3>=3,0.75,cleaned_data!X3=2,0.5,cleaned_data!X3=1,0.25,TRUE,0)} -> 1 | R3: =IF(cleaned_data!Y3="Yes",1,0) -> 1 | S3: =IF(OR(cleaned_data!AF3="GlobalG.A.P.",cleaned_data!AF3="Fairtrade",cleaned_data!AF3="Organic (CERES)"),1, IF(OR(cleaned_data!AF3="SIZA",cleaned_data!AF3="Woolworths TNC",cleaned_data!AF3="Checkers Good Farming"),0.75, IF(cleaned_data!AF3="No Certificate",0, IF(cleaned_data!AF3="Unknown","","")))) | T3: =IF(cleaned_data!AG3="Yes",1,0) -> 0 | U3: =IF(OR(cleaned_data!AD3="No Loan",cleaned_data!AD3="Settled",cleaned_data!AD3="Current"),1, IF(cleaned_data!AD3="In Arrears",0.5, IF(cleaned_data!AD3="Defaulted",0, IF(cleaned_data!AD3="Unknown","","")))) -> 1 | V3: {=_xlfn.IFS(cleaned_data!AE3<=0.2,1, cleaned_data!AE3<=0.5,0.75, cleaned_data!AE3<=1,0.5, cleaned_data!AE3>1,0.25)} -> 1 | W3: =IF(cleaned_data!AJ3="Yes",1,0) -> 1 | X3: {=_xlfn.IFS(cleaned_data!AM3="Yes", 1, cleaned_data!AM3="No", 0, cleaned_data!AM3="Unknown", "")} -> 1 | Y3: {=_xlfn.IFS(cleaned_data!AK3="Solar", 1, cleaned_data!AK3="Generator", 0.75, cleaned_data!AK3="Eskom grid", 0.5, TRUE, "")} -> 0.5 | Z3: {=_xlfn.IFS(cleaned_data!AL3="", "", cleaned_data!AL3<=8, 1, cleaned_data!AL3<=14, 0.75, cleaned_data!AL3<=21, 0.5, cleaned_data!AL3>=22, 0.25)} -> 0.5 | AA3: {=_xlfn.IFS(cleaned_data!AH3=0, 1, cleaned_data!AH3=1, 0.75, cleaned_data!AH3=2, 0.5, cleaned_data!AH3>=3, 0.25)} -> 1 | AB3: {=_xlfn.IFS(cleaned_data!AO3="", "", cleaned_data!AO3>=50, 1, cleaned_data!AO3>=30, 0.75, cleaned_data!AO3>=10, 0.5, cleaned_data!AO3<10, 0.25)} -> 1 | AC3: {=_xlfn.IFS(cleaned_data!AP3>=50,1, cleaned_data!AP3>=30,0.75, cleaned_data!AP3>=10,0.5, cleaned_data!AP3<10,0.25)} -> 0.75 | AD3: {=_xlfn.IFS(cleaned_data!AQ3>=30,1, cleaned_data!AQ3>=20,0.75, cleaned_data!AQ3>=10,0.5, cleaned_data!AQ3<10,0.25)} -> 1 | AE3: {=_xlfn.IFS(cleaned_data!AR3>=75,1, cleaned_data!AR3>=50,0.75, cleaned_data!AR3>=25,0.5, cleaned_data!AR3<25,0.25)} -> 0.75 | AF3: =IF(cleaned_data!AS3="Yes",1,0) -> 0
A4: SME0003 | B4: Vhembe Red | C4: =IF(cleaned_data!K4="Registered",1,0) -> 1 | D4: =IF(cleaned_data!L4="Yes",1,0) -> 1 | E4: =IF(cleaned_data!M4="Yes",1,0) -> 1 | F4: =IF(cleaned_data!O4="Unknown","",IF(cleaned_data!O4="Yes",1,0)) -> 0 | G4: {=_xlfn.IFS(cleaned_data!N4="Owned",1,cleaned_data!N4="Leased",0.75,cleaned_data!N4="State land",0.5,cleaned_data!N4="Communal",0.25)} -> 0.5 | H4: {=_xlfn.IFS(cleaned_data!G4>=10,1,cleaned_data!G4>=5,0.75,cleaned_data!G4>=2,0.5,TRUE,0.25)} -> 1 | I4: =IF(cleaned_data!P4="None",0,1) -> 1 | J4: {=_xlfn.IFS(cleaned_data!H4>=20,1,cleaned_data!H4>=10,0.75,cleaned_data!H4>=5,0.5,cleaned_data!H4>=1,0.25,TRUE,0)} -> 1 | K4: {=_xlfn.IFS(cleaned_data!Q4>=100000,1,cleaned_data!Q4>=50000,0.75,cleaned_data!Q4>=10000,0.5,TRUE,0.25)} -> 1 | L4: {=_xlfn.IFS(cleaned_data!T4="","",cleaned_data!T4<=10,1,cleaned_data!T4<=25,0.75,cleaned_data!T4<=40,0.5, cleaned_data!T4>40,0.25)} -> 1 | M4: =IF(cleaned_data!U4="Yes",1,0) -> 1 | N4: {=_xlfn.IFS(cleaned_data!V4="Unknown","",cleaned_data!V4="Yes",1,TRUE,0)} -> 1 | O4: {=_xlfn.IFS(cleaned_data!S4>=4,1,cleaned_data!S4=3,0.75,cleaned_data!S4=2,0.5,cleaned_data!S4=1,0.25,TRUE,0)} -> 0.25 | P4: {=_xlfn.IFS(cleaned_data!AB4>=50,1,cleaned_data!AB4>=35,0.75,cleaned_data!AB4>=20,0.5,TRUE,0.25)} -> 0.75 | Q4: {=_xlfn.IFS(cleaned_data!X4>=5,1,cleaned_data!X4>=3,0.75,cleaned_data!X4=2,0.5,cleaned_data!X4=1,0.25,TRUE,0)} -> 1 | R4: =IF(cleaned_data!Y4="Yes",1,0) -> 1 | S4: =IF(OR(cleaned_data!AF4="GlobalG.A.P.",cleaned_data!AF4="Fairtrade",cleaned_data!AF4="Organic (CERES)"),1, IF(OR(cleaned_data!AF4="SIZA",cleaned_data!AF4="Woolworths TNC",cleaned_data!AF4="Checkers Good Farming"),0.75, IF(cleaned_data!AF4="No Certificate",0, IF(cleaned_data!AF4="Unknown","","")))) -> 0.75 | T4: =IF(cleaned_data!AG4="Yes",1,0) -> 1 | U4: =IF(OR(cleaned_data!AD4="No Loan",cleaned_data!AD4="Settled",cleaned_data!AD4="Current"),1, IF(cleaned_data!AD4="In Arrears",0.5, IF(cleaned_data!AD4="Defaulted",0, IF(cleaned_data!AD4="Unknown","","")))) -> 1 | V4: {=_xlfn.IFS(cleaned_data!AE4<=0.2,1, cleaned_data!AE4<=0.5,0.75, cleaned_data!AE4<=1,0.5, cleaned_data!AE4>1,0.25)} -> 1 | W4: =IF(cleaned_data!AJ4="Yes",1,0) -> 1 | X4: {=_xlfn.IFS(cleaned_data!AM4="Yes", 1, cleaned_data!AM4="No", 0, cleaned_data!AM4="Unknown", "")} -> 1 | Y4: {=_xlfn.IFS(cleaned_data!AK4="Solar", 1, cleaned_data!AK4="Generator", 0.75, cleaned_data!AK4="Eskom grid", 0.5, TRUE, "")} -> 1 | Z4: {=_xlfn.IFS(cleaned_data!AL4="", "", cleaned_data!AL4<=8, 1, cleaned_data!AL4<=14, 0.75, cleaned_data!AL4<=21, 0.5, cleaned_data!AL4>=22, 0.25)} -> 1 | AA4: {=_xlfn.IFS(cleaned_data!AH4=0, 1, cleaned_data!AH4=1, 0.75, cleaned_data!AH4=2, 0.5, cleaned_data!AH4>=3, 0.25)} -> 1 | AB4: {=_xlfn.IFS(cleaned_data!AO4="", "", cleaned_data!AO4>=50, 1, cleaned_data!AO4>=30, 0.75, cleaned_data!AO4>=10, 0.5, cleaned_data!AO4<10, 0.25)} -> 0.25 | AC4: {=_xlfn.IFS(cleaned_data!AP4>=50,1, cleaned_data!AP4>=30,0.75, cleaned_data!AP4>=10,0.5, cleaned_data!AP4<10,0.25)} -> 1 | AD4: {=_xlfn.IFS(cleaned_data!AQ4>=30,1, cleaned_data!AQ4>=20,0.75, cleaned_data!AQ4>=10,0.5, cleaned_data!AQ4<10,0.25)} -> 1 | AE4: {=_xlfn.IFS(cleaned_data!AR4>=75,1, cleaned_data!AR4>=50,0.75, cleaned_data!AR4>=25,0.5, cleaned_data!AR4<25,0.25)} -> 1 | AF4: =IF(cleaned_data!AS4="Yes",1,0) -> 0
A5: SME0004 | B5: Tsebo Red | C5: =IF(cleaned_data!K5="Registered",1,0) -> 1 | D5: =IF(cleaned_data!L5="Yes",1,0) -> 1 | E5: =IF(cleaned_data!M5="Yes",1,0) -> 1 | F5: =IF(cleaned_data!O5="Unknown","",IF(cleaned_data!O5="Yes",1,0)) -> 1 | G5: {=_xlfn.IFS(cleaned_data!N5="Owned",1,cleaned_data!N5="Leased",0.75,cleaned_data!N5="State land",0.5,cleaned_data!N5="Communal",0.25)} -> 1 | H5: {=_xlfn.IFS(cleaned_data!G5>=10,1,cleaned_data!G5>=5,0.75,cleaned_data!G5>=2,0.5,TRUE,0.25)} -> 1 | I5: =IF(cleaned_data!P5="None",0,1) -> 1 | J5: {=_xlfn.IFS(cleaned_data!H5>=20,1,cleaned_data!H5>=10,0.75,cleaned_data!H5>=5,0.5,cleaned_data!H5>=1,0.25,TRUE,0)} -> 1 | K5: {=_xlfn.IFS(cleaned_data!Q5>=100000,1,cleaned_data!Q5>=50000,0.75,cleaned_data!Q5>=10000,0.5,TRUE,0.25)} -> 1 | L5: {=_xlfn.IFS(cleaned_data!T5="","",cleaned_data!T5<=10,1,cleaned_data!T5<=25,0.75,cleaned_data!T5<=40,0.5, cleaned_data!T5>40,0.25)} -> 1 | M5: =IF(cleaned_data!U5="Yes",1,0) -> 1 | N5: {=_xlfn.IFS(cleaned_data!V5="Unknown","",cleaned_data!V5="Yes",1,TRUE,0)} | O5: {=_xlfn.IFS(cleaned_data!S5>=4,1,cleaned_data!S5=3,0.75,cleaned_data!S5=2,0.5,cleaned_data!S5=1,0.25,TRUE,0)} -> 0.75 | P5: {=_xlfn.IFS(cleaned_data!AB5>=50,1,cleaned_data!AB5>=35,0.75,cleaned_data!AB5>=20,0.5,TRUE,0.25)} -> 0.5 | Q5: {=_xlfn.IFS(cleaned_data!X5>=5,1,cleaned_data!X5>=3,0.75,cleaned_data!X5=2,0.5,cleaned_data!X5=1,0.25,TRUE,0)} -> 0.75 | R5: =IF(cleaned_data!Y5="Yes",1,0) -> 1 | S5: =IF(OR(cleaned_data!AF5="GlobalG.A.P.",cleaned_data!AF5="Fairtrade",cleaned_data!AF5="Organic (CERES)"),1, IF(OR(cleaned_data!AF5="SIZA",cleaned_data!AF5="Woolworths TNC",cleaned_data!AF5="Checkers Good Farming"),0.75, IF(cleaned_data!AF5="No Certificate",0, IF(cleaned_data!AF5="Unknown","","")))) -> 1 | T5: =IF(cleaned_data!AG5="Yes",1,0) -> 1 | U5: =IF(OR(cleaned_data!AD5="No Loan",cleaned_data!AD5="Settled",cleaned_data!AD5="Current"),1, IF(cleaned_data!AD5="In Arrears",0.5, IF(cleaned_data!AD5="Defaulted",0, IF(cleaned_data!AD5="Unknown","","")))) -> 1 | V5: {=_xlfn.IFS(cleaned_data!AE5<=0.2,1, cleaned_data!AE5<=0.5,0.75, cleaned_data!AE5<=1,0.5, cleaned_data!AE5>1,0.25)} -> 1 | W5: =IF(cleaned_data!AJ5="Yes",1,0) -> 1 | X5: {=_xlfn.IFS(cleaned_data!AM5="Yes", 1, cleaned_data!AM5="No", 0, cleaned_data!AM5="Unknown", "")} -> 0 | Y5: {=_xlfn.IFS(cleaned_data!AK5="Solar", 1, cleaned_data!AK5="Generator", 0.75, cleaned_data!AK5="Eskom grid", 0.5, TRUE, "")} -> 0.5 | Z5: {=_xlfn.IFS(cleaned_data!AL5="", "", cleaned_data!AL5<=8, 1, cleaned_data!AL5<=14, 0.75, cleaned_data!AL5<=21, 0.5, cleaned_data!AL5>=22, 0.25)} -> 0.25 | AA5: {=_xlfn.IFS(cleaned_data!AH5=0, 1, cleaned_data!AH5=1, 0.75, cleaned_data!AH5=2, 0.5, cleaned_data!AH5>=3, 0.25)} -> 0.25 | AB5: {=_xlfn.IFS(cleaned_data!AO5="", "", cleaned_data!AO5>=50, 1, cleaned_data!AO5>=30, 0.75, cleaned_data!AO5>=10, 0.5, cleaned_data!AO5<10, 0.25)} -> 1 | AC5: {=_xlfn.IFS(cleaned_data!AP5>=50,1, cleaned_data!AP5>=30,0.75, cleaned_data!AP5>=10,0.5, cleaned_data!AP5<10,0.25)} -> 0.75 | AD5: {=_xlfn.IFS(cleaned_data!AQ5>=30,1, cleaned_data!AQ5>=20,0.75, cleaned_data!AQ5>=10,0.5, cleaned_data!AQ5<10,0.25)} -> 1 | AE5: {=_xlfn.IFS(cleaned_data!AR5>=75,1, cleaned_data!AR5>=50,0.75, cleaned_data!AR5>=25,0.5, cleaned_data!AR5<25,0.25)} -> 0.75 | AF5: =IF(cleaned_data!AS5="Yes",1,0) -> 0
A6: SME0005 | B6: Silver Valley | C6: =IF(cleaned_data!K6="Registered",1,0) -> 1 | D6: =IF(cleaned_data!L6="Yes",1,0) -> 1 | E6: =IF(cleaned_data!M6="Yes",1,0) -> 1 | F6: =IF(cleaned_data!O6="Unknown","",IF(cleaned_data!O6="Yes",1,0)) -> 1 | G6: {=_xlfn.IFS(cleaned_data!N6="Owned",1,cleaned_data!N6="Leased",0.75,cleaned_data!N6="State land",0.5,cleaned_data!N6="Communal",0.25)} -> 1 | H6: {=_xlfn.IFS(cleaned_data!G6>=10,1,cleaned_data!G6>=5,0.75,cleaned_data!G6>=2,0.5,TRUE,0.25)} -> 0.75 | I6: =IF(cleaned_data!P6="None",0,1) -> 1 | J6: {=_xlfn.IFS(cleaned_data!H6>=20,1,cleaned_data!H6>=10,0.75,cleaned_data!H6>=5,0.5,cleaned_data!H6>=1,0.25,TRUE,0)} -> 1 | K6: {=_xlfn.IFS(cleaned_data!Q6>=100000,1,cleaned_data!Q6>=50000,0.75,cleaned_data!Q6>=10000,0.5,TRUE,0.25)} -> 1 | L6: {=_xlfn.IFS(cleaned_data!T6="","",cleaned_data!T6<=10,1,cleaned_data!T6<=25,0.75,cleaned_data!T6<=40,0.5, cleaned_data!T6>40,0.25)} -> 1 | M6: =IF(cleaned_data!U6="Yes",1,0) -> 1 | N6: {=_xlfn.IFS(cleaned_data!V6="Unknown","",cleaned_data!V6="Yes",1,TRUE,0)} -> 0 | O6: {=_xlfn.IFS(cleaned_data!S6>=4,1,cleaned_data!S6=3,0.75,cleaned_data!S6=2,0.5,cleaned_data!S6=1,0.25,TRUE,0)} -> 1 | P6: {=_xlfn.IFS(cleaned_data!AB6>=50,1,cleaned_data!AB6>=35,0.75,cleaned_data!AB6>=20,0.5,TRUE,0.25)} -> 1 | Q6: {=_xlfn.IFS(cleaned_data!X6>=5,1,cleaned_data!X6>=3,0.75,cleaned_data!X6=2,0.5,cleaned_data!X6=1,0.25,TRUE,0)} -> 1 | R6: =IF(cleaned_data!Y6="Yes",1,0) -> 0 | S6: =IF(OR(cleaned_data!AF6="GlobalG.A.P.",cleaned_data!AF6="Fairtrade",cleaned_data!AF6="Organic (CERES)"),1, IF(OR(cleaned_data!AF6="SIZA",cleaned_data!AF6="Woolworths TNC",cleaned_data!AF6="Checkers Good Farming"),0.75, IF(cleaned_data!AF6="No Certificate",0, IF(cleaned_data!AF6="Unknown","","")))) -> 0.75 | T6: =IF(cleaned_data!AG6="Yes",1,0) -> 1 | U6: =IF(OR(cleaned_data!AD6="No Loan",cleaned_data!AD6="Settled",cleaned_data!AD6="Current"),1, IF(cleaned_data!AD6="In Arrears",0.5, IF(cleaned_data!AD6="Defaulted",0, IF(cleaned_data!AD6="Unknown","","")))) -> 1 | V6: {=_xlfn.IFS(cleaned_data!AE6<=0.2,1, cleaned_data!AE6<=0.5,0.75, cleaned_data!AE6<=1,0.5, cleaned_data!AE6>1,0.25)} -> 1 | W6: =IF(cleaned_data!AJ6="Yes",1,0) -> 1 | X6: {=_xlfn.IFS(cleaned_data!AM6="Yes", 1, cleaned_data!AM6="No", 0, cleaned_data!AM6="Unknown", "")} -> 0 | Y6: {=_xlfn.IFS(cleaned_data!AK6="Solar", 1, cleaned_data!AK6="Generator", 0.75, cleaned_data!AK6="Eskom grid", 0.5, TRUE, "")} -> 1 | Z6: {=_xlfn.IFS(cleaned_data!AL6="", "", cleaned_data!AL6<=8, 1, cleaned_data!AL6<=14, 0.75, cleaned_data!AL6<=21, 0.5, cleaned_data!AL6>=22, 0.25)} | AA6: {=_xlfn.IFS(cleaned_data!AH6=0, 1, cleaned_data!AH6=1, 0.75, cleaned_data!AH6=2, 0.5, cleaned_data!AH6>=3, 0.25)} -> 1 | AB6: {=_xlfn.IFS(cleaned_data!AO6="", "", cleaned_data!AO6>=50, 1, cleaned_data!AO6>=30, 0.75, cleaned_data!AO6>=10, 0.5, cleaned_data!AO6<10, 0.25)} -> 0.5 | AC6: {=_xlfn.IFS(cleaned_data!AP6>=50,1, cleaned_data!AP6>=30,0.75, cleaned_data!AP6>=10,0.5, cleaned_data!AP6<10,0.25)} -> 0.5 | AD6: {=_xlfn.IFS(cleaned_data!AQ6>=30,1, cleaned_data!AQ6>=20,0.75, cleaned_data!AQ6>=10,0.5, cleaned_data!AQ6<10,0.25)} -> 0.75 | AE6: {=_xlfn.IFS(cleaned_data!AR6>=75,1, cleaned_data!AR6>=50,0.75, cleaned_data!AR6>=25,0.5, cleaned_data!AR6<25,0.25)} -> 0.75 | AF6: =IF(cleaned_data!AS6="Yes",1,0) -> 1
A7: SME0006 | B7: Tshivhase Silver | C7: =IF(cleaned_data!K7="Registered",1,0) -> 0 | D7: =IF(cleaned_data!L7="Yes",1,0) -> 1 | E7: =IF(cleaned_data!M7="Yes",1,0) -> 0 | F7: =IF(cleaned_data!O7="Unknown","",IF(cleaned_data!O7="Yes",1,0)) -> 0 | G7: {=_xlfn.IFS(cleaned_data!N7="Owned",1,cleaned_data!N7="Leased",0.75,cleaned_data!N7="State land",0.5,cleaned_data!N7="Communal",0.25)} -> 0.75 | H7: {=_xlfn.IFS(cleaned_data!G7>=10,1,cleaned_data!G7>=5,0.75,cleaned_data!G7>=2,0.5,TRUE,0.25)} -> 0.75 | I7: =IF(cleaned_data!P7="None",0,1) -> 1 | J7: {=_xlfn.IFS(cleaned_data!H7>=20,1,cleaned_data!H7>=10,0.75,cleaned_data!H7>=5,0.5,cleaned_data!H7>=1,0.25,TRUE,0)} -> 1 | K7: {=_xlfn.IFS(cleaned_data!Q7>=100000,1,cleaned_data!Q7>=50000,0.75,cleaned_data!Q7>=10000,0.5,TRUE,0.25)} -> 1 | L7: {=_xlfn.IFS(cleaned_data!T7="","",cleaned_data!T7<=10,1,cleaned_data!T7<=25,0.75,cleaned_data!T7<=40,0.5, cleaned_data!T7>40,0.25)} -> 0.75 | M7: =IF(cleaned_data!U7="Yes",1,0) -> 0 | N7: {=_xlfn.IFS(cleaned_data!V7="Unknown","",cleaned_data!V7="Yes",1,TRUE,0)} -> 0 | O7: {=_xlfn.IFS(cleaned_data!S7>=4,1,cleaned_data!S7=3,0.75,cleaned_data!S7=2,0.5,cleaned_data!S7=1,0.25,TRUE,0)} -> 0.5 | P7: {=_xlfn.IFS(cleaned_data!AB7>=50,1,cleaned_data!AB7>=35,0.75,cleaned_data!AB7>=20,0.5,TRUE,0.25)} -> 0.75 | Q7: {=_xlfn.IFS(cleaned_data!X7>=5,1,cleaned_data!X7>=3,0.75,cleaned_data!X7=2,0.5,cleaned_data!X7=1,0.25,TRUE,0)} -> 1 | R7: =IF(cleaned_data!Y7="Yes",1,0) -> 1 | S7: =IF(OR(cleaned_data!AF7="GlobalG.A.P.",cleaned_data!AF7="Fairtrade",cleaned_data!AF7="Organic (CERES)"),1, IF(OR(cleaned_data!AF7="SIZA",cleaned_data!AF7="Woolworths TNC",cleaned_data!AF7="Checkers Good Farming"),0.75, IF(cleaned_data!AF7="No Certificate",0, IF(cleaned_data!AF7="Unknown","","")))) -> 0.75 | T7: =IF(cleaned_data!AG7="Yes",1,0) -> 1 | U7: =IF(OR(cleaned_data!AD7="No Loan",cleaned_data!AD7="Settled",cleaned_data!AD7="Current"),1, IF(cleaned_data!AD7="In Arrears",0.5, IF(cleaned_data!AD7="Defaulted",0, IF(cleaned_data!AD7="Unknown","","")))) -> 1 | V7: {=_xlfn.IFS(cleaned_data!AE7<=0.2,1, cleaned_data!AE7<=0.5,0.75, cleaned_data!AE7<=1,0.5, cleaned_data!AE7>1,0.25)} -> 1 | W7: =IF(cleaned_data!AJ7="Yes",1,0) -> 1 | X7: {=_xlfn.IFS(cleaned_data!AM7="Yes", 1, cleaned_data!AM7="No", 0, cleaned_data!AM7="Unknown", "")} -> 1 | Y7: {=_xlfn.IFS(cleaned_data!AK7="Solar", 1, cleaned_data!AK7="Generator", 0.75, cleaned_data!AK7="Eskom grid", 0.5, TRUE, "")} -> 0.5 | Z7: {=_xlfn.IFS(cleaned_data!AL7="", "", cleaned_data!AL7<=8, 1, cleaned_data!AL7<=14, 0.75, cleaned_data!AL7<=21, 0.5, cleaned_data!AL7>=22, 0.25)} -> 1 | AA7: {=_xlfn.IFS(cleaned_data!AH7=0, 1, cleaned_data!AH7=1, 0.75, cleaned_data!AH7=2, 0.5, cleaned_data!AH7>=3, 0.25)} -> 0.75 | AB7: {=_xlfn.IFS(cleaned_data!AO7="", "", cleaned_data!AO7>=50, 1, cleaned_data!AO7>=30, 0.75, cleaned_data!AO7>=10, 0.5, cleaned_data!AO7<10, 0.25)} -> 0.25 | AC7: {=_xlfn.IFS(cleaned_data!AP7>=50,1, cleaned_data!AP7>=30,0.75, cleaned_data!AP7>=10,0.5, cleaned_data!AP7<10,0.25)} -> 1 | AD7: {=_xlfn.IFS(cleaned_data!AQ7>=30,1, cleaned_data!AQ7>=20,0.75, cleaned_data!AQ7>=10,0.5, cleaned_data!AQ7<10,0.25)} -> 0.75 | AE7: {=_xlfn.IFS(cleaned_data!AR7>=75,1, cleaned_data!AR7>=50,0.75, cleaned_data!AR7>=25,0.5, cleaned_data!AR7<25,0.25)} -> 1 | AF7: =IF(cleaned_data!AS7="Yes",1,0) -> 1
A8: SME0007 | B8: Amandla Golden | C8: =IF(cleaned_data!K8="Registered",1,0) -> 1 | D8: =IF(cleaned_data!L8="Yes",1,0) -> 1 | E8: =IF(cleaned_data!M8="Yes",1,0) -> 1 | F8: =IF(cleaned_data!O8="Unknown","",IF(cleaned_data!O8="Yes",1,0)) | G8: {=_xlfn.IFS(cleaned_data!N8="Owned",1,cleaned_data!N8="Leased",0.75,cleaned_data!N8="State land",0.5,cleaned_data!N8="Communal",0.25)} -> 0.75 | H8: {=_xlfn.IFS(cleaned_data!G8>=10,1,cleaned_data!G8>=5,0.75,cleaned_data!G8>=2,0.5,TRUE,0.25)} -> 1 | I8: =IF(cleaned_data!P8="None",0,1) -> 1 | J8: {=_xlfn.IFS(cleaned_data!H8>=20,1,cleaned_data!H8>=10,0.75,cleaned_data!H8>=5,0.5,cleaned_data!H8>=1,0.25,TRUE,0)} -> 1 | K8: {=_xlfn.IFS(cleaned_data!Q8>=100000,1,cleaned_data!Q8>=50000,0.75,cleaned_data!Q8>=10000,0.5,TRUE,0.25)} -> 1 | L8: {=_xlfn.IFS(cleaned_data!T8="","",cleaned_data!T8<=10,1,cleaned_data!T8<=25,0.75,cleaned_data!T8<=40,0.5, cleaned_data!T8>40,0.25)} -> 0.75 | M8: =IF(cleaned_data!U8="Yes",1,0) -> 0 | N8: {=_xlfn.IFS(cleaned_data!V8="Unknown","",cleaned_data!V8="Yes",1,TRUE,0)} -> 0 | O8: {=_xlfn.IFS(cleaned_data!S8>=4,1,cleaned_data!S8=3,0.75,cleaned_data!S8=2,0.5,cleaned_data!S8=1,0.25,TRUE,0)} -> 1 | P8: {=_xlfn.IFS(cleaned_data!AB8>=50,1,cleaned_data!AB8>=35,0.75,cleaned_data!AB8>=20,0.5,TRUE,0.25)} -> 0.75 | Q8: {=_xlfn.IFS(cleaned_data!X8>=5,1,cleaned_data!X8>=3,0.75,cleaned_data!X8=2,0.5,cleaned_data!X8=1,0.25,TRUE,0)} -> 1 | R8: =IF(cleaned_data!Y8="Yes",1,0) -> 1 | S8: =IF(OR(cleaned_data!AF8="GlobalG.A.P.",cleaned_data!AF8="Fairtrade",cleaned_data!AF8="Organic (CERES)"),1, IF(OR(cleaned_data!AF8="SIZA",cleaned_data!AF8="Woolworths TNC",cleaned_data!AF8="Checkers Good Farming"),0.75, IF(cleaned_data!AF8="No Certificate",0, IF(cleaned_data!AF8="Unknown","","")))) -> 1 | T8: =IF(cleaned_data!AG8="Yes",1,0) -> 0 | U8: =IF(OR(cleaned_data!AD8="No Loan",cleaned_data!AD8="Settled",cleaned_data!AD8="Current"),1, IF(cleaned_data!AD8="In Arrears",0.5, IF(cleaned_data!AD8="Defaulted",0, IF(cleaned_data!AD8="Unknown","","")))) -> 1 | V8: {=_xlfn.IFS(cleaned_data!AE8<=0.2,1, cleaned_data!AE8<=0.5,0.75, cleaned_data!AE8<=1,0.5, cleaned_data!AE8>1,0.25)} -> 1 | W8: =IF(cleaned_data!AJ8="Yes",1,0) -> 1 | X8: {=_xlfn.IFS(cleaned_data!AM8="Yes", 1, cleaned_data!AM8="No", 0, cleaned_data!AM8="Unknown", "")} -> 1 | Y8: {=_xlfn.IFS(cleaned_data!AK8="Solar", 1, cleaned_data!AK8="Generator", 0.75, cleaned_data!AK8="Eskom grid", 0.5, TRUE, "")} -> 0.5 | Z8: {=_xlfn.IFS(cleaned_data!AL8="", "", cleaned_data!AL8<=8, 1, cleaned_data!AL8<=14, 0.75, cleaned_data!AL8<=21, 0.5, cleaned_data!AL8>=22, 0.25)} -> 0.5 | AA8: {=_xlfn.IFS(cleaned_data!AH8=0, 1, cleaned_data!AH8=1, 0.75, cleaned_data!AH8=2, 0.5, cleaned_data!AH8>=3, 0.25)} -> 0.25 | AB8: {=_xlfn.IFS(cleaned_data!AO8="", "", cleaned_data!AO8>=50, 1, cleaned_data!AO8>=30, 0.75, cleaned_data!AO8>=10, 0.5, cleaned_data!AO8<10, 0.25)} -> 1 | AC8: {=_xlfn.IFS(cleaned_data!AP8>=50,1, cleaned_data!AP8>=30,0.75, cleaned_data!AP8>=10,0.5, cleaned_data!AP8<10,0.25)} -> 1 | AD8: {=_xlfn.IFS(cleaned_data!AQ8>=30,1, cleaned_data!AQ8>=20,0.75, cleaned_data!AQ8>=10,0.5, cleaned_data!AQ8<10,0.25)} -> 0.75 | AE8: {=_xlfn.IFS(cleaned_data!AR8>=75,1, cleaned_data!AR8>=50,0.75, cleaned_data!AR8>=25,0.5, cleaned_data!AR8<25,0.25)} -> 0.5 | AF8: =IF(cleaned_data!AS8="Yes",1,0) -> 0
A9: SME0008 | B9: Ubuntu Plaas | C9: =IF(cleaned_data!K9="Registered",1,0) -> 1 | D9: =IF(cleaned_data!L9="Yes",1,0) -> 1 | E9: =IF(cleaned_data!M9="Yes",1,0) -> 1 | F9: =IF(cleaned_data!O9="Unknown","",IF(cleaned_data!O9="Yes",1,0)) -> 1 | G9: {=_xlfn.IFS(cleaned_data!N9="Owned",1,cleaned_data!N9="Leased",0.75,cleaned_data!N9="State land",0.5,cleaned_data!N9="Communal",0.25)} -> 0.75 | H9: {=_xlfn.IFS(cleaned_data!G9>=10,1,cleaned_data!G9>=5,0.75,cleaned_data!G9>=2,0.5,TRUE,0.25)} -> 1 | I9: =IF(cleaned_data!P9="None",0,1) -> 1 | J9: {=_xlfn.IFS(cleaned_data!H9>=20,1,cleaned_data!H9>=10,0.75,cleaned_data!H9>=5,0.5,cleaned_data!H9>=1,0.25,TRUE,0)} -> 1 | K9: {=_xlfn.IFS(cleaned_data!Q9>=100000,1,cleaned_data!Q9>=50000,0.75,cleaned_data!Q9>=10000,0.5,TRUE,0.25)} -> 1 | L9: {=_xlfn.IFS(cleaned_data!T9="","",cleaned_data!T9<=10,1,cleaned_data!T9<=25,0.75,cleaned_data!T9<=40,0.5, cleaned_data!T9>40,0.25)} -> 1 | M9: =IF(cleaned_data!U9="Yes",1,0) -> 1 | N9: {=_xlfn.IFS(cleaned_data!V9="Unknown","",cleaned_data!V9="Yes",1,TRUE,0)} -> 1 | O9: {=_xlfn.IFS(cleaned_data!S9>=4,1,cleaned_data!S9=3,0.75,cleaned_data!S9=2,0.5,cleaned_data!S9=1,0.25,TRUE,0)} -> 0.25 | P9: {=_xlfn.IFS(cleaned_data!AB9>=50,1,cleaned_data!AB9>=35,0.75,cleaned_data!AB9>=20,0.5,TRUE,0.25)} -> 1 | Q9: {=_xlfn.IFS(cleaned_data!X9>=5,1,cleaned_data!X9>=3,0.75,cleaned_data!X9=2,0.5,cleaned_data!X9=1,0.25,TRUE,0)} -> 1 | R9: =IF(cleaned_data!Y9="Yes",1,0) -> 0 | S9: =IF(OR(cleaned_data!AF9="GlobalG.A.P.",cleaned_data!AF9="Fairtrade",cleaned_data!AF9="Organic (CERES)"),1, IF(OR(cleaned_data!AF9="SIZA",cleaned_data!AF9="Woolworths TNC",cleaned_data!AF9="Checkers Good Farming"),0.75, IF(cleaned_data!AF9="No Certificate",0, IF(cleaned_data!AF9="Unknown","","")))) -> 1 | T9: =IF(cleaned_data!AG9="Yes",1,0) -> 1 | U9: =IF(OR(cleaned_data!AD9="No Loan",cleaned_data!AD9="Settled",cleaned_data!AD9="Current"),1, IF(cleaned_data!AD9="In Arrears",0.5, IF(cleaned_data!AD9="Defaulted",0, IF(cleaned_data!AD9="Unknown","","")))) -> 1 | V9: {=_xlfn.IFS(cleaned_data!AE9<=0.2,1, cleaned_data!AE9<=0.5,0.75, cleaned_data!AE9<=1,0.5, cleaned_data!AE9>1,0.25)} -> 1 | W9: =IF(cleaned_data!AJ9="Yes",1,0) -> 1 | X9: {=_xlfn.IFS(cleaned_data!AM9="Yes", 1, cleaned_data!AM9="No", 0, cleaned_data!AM9="Unknown", "")} -> 1 | Y9: {=_xlfn.IFS(cleaned_data!AK9="Solar", 1, cleaned_data!AK9="Generator", 0.75, cleaned_data!AK9="Eskom grid", 0.5, TRUE, "")} -> 0.5 | Z9: {=_xlfn.IFS(cleaned_data!AL9="", "", cleaned_data!AL9<=8, 1, cleaned_data!AL9<=14, 0.75, cleaned_data!AL9<=21, 0.5, cleaned_data!AL9>=22, 0.25)} -> 0.25 | AA9: {=_xlfn.IFS(cleaned_data!AH9=0, 1, cleaned_data!AH9=1, 0.75, cleaned_data!AH9=2, 0.5, cleaned_data!AH9>=3, 0.25)} -> 1 | AB9: {=_xlfn.IFS(cleaned_data!AO9="", "", cleaned_data!AO9>=50, 1, cleaned_data!AO9>=30, 0.75, cleaned_data!AO9>=10, 0.5, cleaned_data!AO9<10, 0.25)} -> 1 | AC9: {=_xlfn.IFS(cleaned_data!AP9>=50,1, cleaned_data!AP9>=30,0.75, cleaned_data!AP9>=10,0.5, cleaned_data!AP9<10,0.25)} -> 1 | AD9: {=_xlfn.IFS(cleaned_data!AQ9>=30,1, cleaned_data!AQ9>=20,0.75, cleaned_data!AQ9>=10,0.5, cleaned_data!AQ9<10,0.25)} -> 0.5 | AE9: {=_xlfn.IFS(cleaned_data!AR9>=75,1, cleaned_data!AR9>=50,0.75, cleaned_data!AR9>=25,0.5, cleaned_data!AR9<25,0.25)} -> 0.5 | AF9: =IF(cleaned_data!AS9="Yes",1,0) -> 1
A10: SME0009 | B10: Mashamba Rainbow | C10: =IF(cleaned_data!K10="Registered",1,0) -> 1 | D10: =IF(cleaned_data!L10="Yes",1,0) -> 0 | E10: =IF(cleaned_data!M10="Yes",1,0) -> 1 | F10: =IF(cleaned_data!O10="Unknown","",IF(cleaned_data!O10="Yes",1,0)) -> 1 | G10: {=_xlfn.IFS(cleaned_data!N10="Owned",1,cleaned_data!N10="Leased",0.75,cleaned_data!N10="State land",0.5,cleaned_data!N10="Communal",0.25)} -> 0.75 | H10: {=_xlfn.IFS(cleaned_data!G10>=10,1,cleaned_data!G10>=5,0.75,cleaned_data!G10>=2,0.5,TRUE,0.25)} -> 0.75 | I10: =IF(cleaned_data!P10="None",0,1) -> 1 | J10: {=_xlfn.IFS(cleaned_data!H10>=20,1,cleaned_data!H10>=10,0.75,cleaned_data!H10>=5,0.5,cleaned_data!H10>=1,0.25,TRUE,0)} -> 0.75 | K10: {=_xlfn.IFS(cleaned_data!Q10>=100000,1,cleaned_data!Q10>=50000,0.75,cleaned_data!Q10>=10000,0.5,TRUE,0.25)} -> 1 | L10: {=_xlfn.IFS(cleaned_data!T10="","",cleaned_data!T10<=10,1,cleaned_data!T10<=25,0.75,cleaned_data!T10<=40,0.5, cleaned_data!T10>40,0.25)} -> 0.75 | M10: =IF(cleaned_data!U10="Yes",1,0) -> 1 | N10: {=_xlfn.IFS(cleaned_data!V10="Unknown","",cleaned_data!V10="Yes",1,TRUE,0)} -> 1 | O10: {=_xlfn.IFS(cleaned_data!S10>=4,1,cleaned_data!S10=3,0.75,cleaned_data!S10=2,0.5,cleaned_data!S10=1,0.25,TRUE,0)} -> 0.75 | P10: {=_xlfn.IFS(cleaned_data!AB10>=50,1,cleaned_data!AB10>=35,0.75,cleaned_data!AB10>=20,0.5,TRUE,0.25)} -> 0.75 | Q10: {=_xlfn.IFS(cleaned_data!X10>=5,1,cleaned_data!X10>=3,0.75,cleaned_data!X10=2,0.5,cleaned_data!X10=1,0.25,TRUE,0)} -> 1 | R10: =IF(cleaned_data!Y10="Yes",1,0) -> 1 | S10: =IF(OR(cleaned_data!AF10="GlobalG.A.P.",cleaned_data!AF10="Fairtrade",cleaned_data!AF10="Organic (CERES)"),1, IF(OR(cleaned_data!AF10="SIZA",cleaned_data!AF10="Woolworths TNC",cleaned_data!AF10="Checkers Good Farming"),0.75, IF(cleaned_data!AF10="No Certificate",0, IF(cleaned_data!AF10="Unknown","","")))) -> 0.75 | T10: =IF(cleaned_data!AG10="Yes",1,0) -> 0 | U10: =IF(OR(cleaned_data!AD10="No Loan",cleaned_data!AD10="Settled",cleaned_data!AD10="Current"),1, IF(cleaned_data!AD10="In Arrears",0.5, IF(cleaned_data!AD10="Defaulted",0, IF(cleaned_data!AD10="Unknown","","")))) -> 1 | V10: {=_xlfn.IFS(cleaned_data!AE10<=0.2,1, cleaned_data!AE10<=0.5,0.75, cleaned_data!AE10<=1,0.5, cleaned_data!AE10>1,0.25)} -> 1 | W10: =IF(cleaned_data!AJ10="Yes",1,0) -> 1 | X10: {=_xlfn.IFS(cleaned_data!AM10="Yes", 1, cleaned_data!AM10="No", 0, cleaned_data!AM10="Unknown", "")} -> 1 | Y10: {=_xlfn.IFS(cleaned_data!AK10="Solar", 1, cleaned_data!AK10="Generator", 0.75, cleaned_data!AK10="Eskom grid", 0.5, TRUE, "")} -> 0.5 | Z10: {=_xlfn.IFS(cleaned_data!AL10="", "", cleaned_data!AL10<=8, 1, cleaned_data!AL10<=14, 0.75, cleaned_data!AL10<=21, 0.5, cleaned_data!AL10>=22, 0.25)} -> 0.5 | AA10: {=_xlfn.IFS(cleaned_data!AH10=0, 1, cleaned_data!AH10=1, 0.75, cleaned_data!AH10=2, 0.5, cleaned_data!AH10>=3, 0.25)} -> 0.75 | AB10: {=_xlfn.IFS(cleaned_data!AO10="", "", cleaned_data!AO10>=50, 1, cleaned_data!AO10>=30, 0.75, cleaned_data!AO10>=10, 0.5, cleaned_data!AO10<10, 0.25)} -> 1 | AC10: {=_xlfn.IFS(cleaned_data!AP10>=50,1, cleaned_data!AP10>=30,0.75, cleaned_data!AP10>=10,0.5, cleaned_data!AP10<10,0.25)} -> 0.5 | AD10: {=_xlfn.IFS(cleaned_data!AQ10>=30,1, cleaned_data!AQ10>=20,0.75, cleaned_data!AQ10>=10,0.5, cleaned_data!AQ10<10,0.25)} -> 1 | AE10: {=_xlfn.IFS(cleaned_data!AR10>=75,1, cleaned_data!AR10>=50,0.75, cleaned_data!AR10>=25,0.5, cleaned_data!AR10<25,0.25)} -> 0.75 | AF10: =IF(cleaned_data!AS10="Yes",1,0) -> 0
A11: SME0010 | B11: Green Valley | C11: =IF(cleaned_data!K11="Registered",1,0) -> 1 | D11: =IF(cleaned_data!L11="Yes",1,0) -> 0 | E11: =IF(cleaned_data!M11="Yes",1,0) -> 1 | F11: =IF(cleaned_data!O11="Unknown","",IF(cleaned_data!O11="Yes",1,0)) -> 1 | G11: {=_xlfn.IFS(cleaned_data!N11="Owned",1,cleaned_data!N11="Leased",0.75,cleaned_data!N11="State land",0.5,cleaned_data!N11="Communal",0.25)} -> 1 | H11: {=_xlfn.IFS(cleaned_data!G11>=10,1,cleaned_data!G11>=5,0.75,cleaned_data!G11>=2,0.5,TRUE,0.25)} -> 1 | I11: =IF(cleaned_data!P11="None",0,1) -> 1 | J11: {=_xlfn.IFS(cleaned_data!H11>=20,1,cleaned_data!H11>=10,0.75,cleaned_data!H11>=5,0.5,cleaned_data!H11>=1,0.25,TRUE,0)} -> 1 | K11: {=_xlfn.IFS(cleaned_data!Q11>=100000,1,cleaned_data!Q11>=50000,0.75,cleaned_data!Q11>=10000,0.5,TRUE,0.25)} -> 0.25 | L11: {=_xlfn.IFS(cleaned_data!T11="","",cleaned_data!T11<=10,1,cleaned_data!T11<=25,0.75,cleaned_data!T11<=40,0.5, cleaned_data!T11>40,0.25)} -> 1 | M11: =IF(cleaned_data!U11="Yes",1,0) -> 1 | N11: {=_xlfn.IFS(cleaned_data!V11="Unknown","",cleaned_data!V11="Yes",1,TRUE,0)} -> 1 | O11: {=_xlfn.IFS(cleaned_data!S11>=4,1,cleaned_data!S11=3,0.75,cleaned_data!S11=2,0.5,cleaned_data!S11=1,0.25,TRUE,0)} -> 1 | P11: {=_xlfn.IFS(cleaned_data!AB11>=50,1,cleaned_data!AB11>=35,0.75,cleaned_data!AB11>=20,0.5,TRUE,0.25)} -> 0.75 | Q11: {=_xlfn.IFS(cleaned_data!X11>=5,1,cleaned_data!X11>=3,0.75,cleaned_data!X11=2,0.5,cleaned_data!X11=1,0.25,TRUE,0)} -> 1 | R11: =IF(cleaned_data!Y11="Yes",1,0) -> 1 | S11: =IF(OR(cleaned_data!AF11="GlobalG.A.P.",cleaned_data!AF11="Fairtrade",cleaned_data!AF11="Organic (CERES)"),1, IF(OR(cleaned_data!AF11="SIZA",cleaned_data!AF11="Woolworths TNC",cleaned_data!AF11="Checkers Good Farming"),0.75, IF(cleaned_data!AF11="No Certificate",0, IF(cleaned_data!AF11="Unknown","","")))) -> 0.75 | T11: =IF(cleaned_data!AG11="Yes",1,0) -> 0 | U11: =IF(OR(cleaned_data!AD11="No Loan",cleaned_data!AD11="Settled",cleaned_data!AD11="Current"),1, IF(cleaned_data!AD11="In Arrears",0.5, IF(cleaned_data!AD11="Defaulted",0, IF(cleaned_data!AD11="Unknown","","")))) -> 1 | V11: {=_xlfn.IFS(cleaned_data!AE11<=0.2,1, cleaned_data!AE11<=0.5,0.75, cleaned_data!AE11<=1,0.5, cleaned_data!AE11>1,0.25)} -> 0.25 | W11: =IF(cleaned_data!AJ11="Yes",1,0) -> 1 | X11: {=_xlfn.IFS(cleaned_data!AM11="Yes", 1, cleaned_data!AM11="No", 0, cleaned_data!AM11="Unknown", "")} -> 1 | Y11: {=_xlfn.IFS(cleaned_data!AK11="Solar", 1, cleaned_data!AK11="Generator", 0.75, cleaned_data!AK11="Eskom grid", 0.5, TRUE, "")} -> 0.75 | Z11: {=_xlfn.IFS(cleaned_data!AL11="", "", cleaned_data!AL11<=8, 1, cleaned_data!AL11<=14, 0.75, cleaned_data!AL11<=21, 0.5, cleaned_data!AL11>=22, 0.25)} -> 1 | AA11: {=_xlfn.IFS(cleaned_data!AH11=0, 1, cleaned_data!AH11=1, 0.75, cleaned_data!AH11=2, 0.5, cleaned_data!AH11>=3, 0.25)} -> 1 | AB11: {=_xlfn.IFS(cleaned_data!AO11="", "", cleaned_data!AO11>=50, 1, cleaned_data!AO11>=30, 0.75, cleaned_data!AO11>=10, 0.5, cleaned_data!AO11<10, 0.25)} -> 1 | AC11: {=_xlfn.IFS(cleaned_data!AP11>=50,1, cleaned_data!AP11>=30,0.75, cleaned_data!AP11>=10,0.5, cleaned_data!AP11<10,0.25)} -> 0.5 | AD11: {=_xlfn.IFS(cleaned_data!AQ11>=30,1, cleaned_data!AQ11>=20,0.75, cleaned_data!AQ11>=10,0.5, cleaned_data!AQ11<10,0.25)} -> 1 | AE11: {=_xlfn.IFS(cleaned_data!AR11>=75,1, cleaned_data!AR11>=50,0.75, cleaned_data!AR11>=25,0.5, cleaned_data!AR11<25,0.25)} -> 0.75 | AF11: =IF(cleaned_data!AS11="Yes",1,0) -> 0
